<robot name="">
	<link name="world">
		<inertial>
			<origin rpy="0.00000 -0.00000 0.00000" xyz="0.00000 0.00000 0.00000" />
			<mass value="0.00000" />
			<inertia ixx="0.00000" ixy="0" ixz="0" iyy="0.00000" iyz="0" izz="0.00000" />
		</inertial>
	</link>
	<link name="base_link">
		<inertial>
			<origin rpy="0.00000 -0.00000 0.00000" xyz="0.00000 0.00000 0.00000" />
			<mass value="4.00000" />
			<inertia ixx="0.01063" ixy="0" ixz="0" iyy="0.00875" iyz="0" izz="0.01809" />
		</inertial>
		<visual>
			<origin rpy="0.00000 -0.00000 0.00000" xyz="0.00000 0.00000 0.00000" />
			<geometry>
				<mesh filename="rlbotics/envs/models/robots/universal_robots/ur10/meshes/ur10/visual/base.dae" scale="1.00000 1.00000 1.00000" />
			</geometry>
			<material name="0">
				<color rgba="0.70000 0.70000 0.70000 1.00000" />
			</material>
		</visual>
		<collision>
			<origin rpy="0.00000 -0.00000 0.00000" xyz="0.00000 0.00000 0.00000" />
			<geometry>
				<mesh filename="rlbotics/envs/models/robots/universal_robots/ur10/meshes/ur10/collision/base.stl" scale="1.00000 1.00000 1.00000" />
			</geometry>
		</collision>
	</link>
	<link name="shoulder_link">
		<inertial>
			<origin rpy="0.00000 -0.00000 0.00000" xyz="0.00000 0.00000 0.00000" />
			<mass value="7.77800" />
			<inertia ixx="0.03989" ixy="0" ixz="0" iyy="0.03770" iyz="0" izz="0.03412" />
		</inertial>
		<visual>
			<origin rpy="0.00000 -0.00000 0.00000" xyz="0.00000 0.00000 0.00000" />
			<geometry>
				<mesh filename="rlbotics/envs/models/robots/universal_robots/ur10/meshes/ur10/visual/shoulder.dae" scale="1.00000 1.00000 1.00000" />
			</geometry>
			<material name="1">
				<color rgba="0.70000 0.70000 0.70000 1.00000" />
			</material>
		</visual>
		<collision>
			<origin rpy="0.00000 -0.00000 0.00000" xyz="0.00000 0.00000 0.00000" />
			<geometry>
				<mesh filename="rlbotics/envs/models/robots/universal_robots/ur10/meshes/ur10/collision/shoulder.stl" scale="1.00000 1.00000 1.00000" />
			</geometry>
		</collision>
	</link>
	<link name="upper_arm_link">
		<inertial>
			<origin rpy="0.00000 -0.00000 0.00000" xyz="0.00000 -0.04500 0.30600" />
			<mass value="12.93000" />
			<inertia ixx="0.65013" ixy="0" ixz="0" iyy="0.64040" iyz="0" izz="0.06264" />
		</inertial>
		<visual>
			<origin rpy="0.00000 -0.00000 0.00000" xyz="0.00000 0.00000 0.00000" />
			<geometry>
				<mesh filename="rlbotics/envs/models/robots/universal_robots/ur10/meshes/ur10/visual/upperarm.dae" scale="1.00000 1.00000 1.00000" />
			</geometry>
			<material name="2">
				<color rgba="0.70000 0.70000 0.70000 1.00000" />
			</material>
		</visual>
		<collision>
			<origin rpy="0.00000 -0.00000 0.00000" xyz="0.00000 0.00000 0.00000" />
			<geometry>
				<mesh filename="rlbotics/envs/models/robots/universal_robots/ur10/meshes/ur10/collision/upperarm.stl" scale="1.00000 1.00000 1.00000" />
			</geometry>
		</collision>
	</link>
	<link name="forearm_link">
		<inertial>
			<origin rpy="0.00000 -0.00000 0.00000" xyz="0.00000 0.00000 0.28615" />
			<mass value="3.87000" />
			<inertia ixx="0.15749" ixy="0" ixz="0" iyy="0.15609" iyz="0" izz="0.01167" />
		</inertial>
		<visual>
			<origin rpy="0.00000 -0.00000 0.00000" xyz="0.00000 0.00000 0.00000" />
			<geometry>
				<mesh filename="rlbotics/envs/models/robots/universal_robots/ur10/meshes/ur10/visual/forearm.dae" scale="1.00000 1.00000 1.00000" />
			</geometry>
			<material name="3">
				<color rgba="0.70000 0.70000 0.70000 1.00000" />
			</material>
		</visual>
		<collision>
			<origin rpy="0.00000 -0.00000 0.00000" xyz="0.00000 0.00000 0.00000" />
			<geometry>
				<mesh filename="rlbotics/envs/models/robots/universal_robots/ur10/meshes/ur10/collision/forearm.stl" scale="1.00000 1.00000 1.00000" />
			</geometry>
		</collision>
	</link>
	<link name="wrist_1_link">
		<inertial>
			<origin rpy="0.00000 -0.00000 0.00000" xyz="0.00000 0.11490 0.00000" />
			<mass value="1.96000" />
			<inertia ixx="0.00438" ixy="0" ixz="0" iyy="0.00408" iyz="0" izz="0.00338" />
		</inertial>
		<visual>
			<origin rpy="0.00000 -0.00000 0.00000" xyz="0.00000 0.00000 0.00000" />
			<geometry>
				<mesh filename="rlbotics/envs/models/robots/universal_robots/ur10/meshes/ur10/visual/wrist1.dae" scale="1.00000 1.00000 1.00000" />
			</geometry>
			<material name="4">
				<color rgba="0.70000 0.70000 0.70000 1.00000" />
			</material>
		</visual>
		<collision>
			<origin rpy="0.00000 -0.00000 0.00000" xyz="0.00000 0.00000 0.00000" />
			<geometry>
				<mesh filename="rlbotics/envs/models/robots/universal_robots/ur10/meshes/ur10/collision/wrist1.stl" scale="1.00000 1.00000 1.00000" />
			</geometry>
		</collision>
	</link>
	<link name="wrist_2_link">
		<inertial>
			<origin rpy="0.00000 -0.00000 0.00000" xyz="0.00000 0.00000 0.11570" />
			<mass value="1.96000" />
			<inertia ixx="0.00438" ixy="0" ixz="0" iyy="0.00338" iyz="0" izz="0.00409" />
		</inertial>
		<visual>
			<origin rpy="0.00000 -0.00000 0.00000" xyz="0.00000 0.00000 0.00000" />
			<geometry>
				<mesh filename="rlbotics/envs/models/robots/universal_robots/ur10/meshes/ur10/visual/wrist2.dae" scale="1.00000 1.00000 1.00000" />
			</geometry>
			<material name="5">
				<color rgba="0.70000 0.70000 0.70000 1.00000" />
			</material>
		</visual>
		<collision>
			<origin rpy="0.00000 -0.00000 0.00000" xyz="0.00000 0.00000 0.00000" />
			<geometry>
				<mesh filename="rlbotics/envs/models/robots/universal_robots/ur10/meshes/ur10/collision/wrist2.stl" scale="1.00000 1.00000 1.00000" />
			</geometry>
		</collision>
	</link>
	<link name="wrist_3_link">
		<inertial>
			<origin rpy="1.57080 -0.00000 0.00000" xyz="0.00000 0.07695 0.00000" />
			<mass value="0.20200" />
			<inertia ixx="0.00018" ixy="0" ixz="0" iyy="0.00018" iyz="0" izz="0.00031" />
		</inertial>
		<visual>
			<origin rpy="0.00000 -0.00000 0.00000" xyz="0.00000 0.00000 0.00000" />
			<geometry>
				<mesh filename="rlbotics/envs/models/robots/universal_robots/ur10/meshes/ur10/visual/wrist3.dae" scale="1.00000 1.00000 1.00000" />
			</geometry>
			<material name="6">
				<color rgba="0.70000 0.70000 0.70000 1.00000" />
			</material>
		</visual>
		<collision>
			<origin rpy="0.00000 -0.00000 0.00000" xyz="0.00000 0.00000 -0.00000" />
			<geometry>
				<mesh filename="rlbotics/envs/models/robots/universal_robots/ur10/meshes/ur10/collision/wrist3.stl" scale="1.00000 1.00000 1.00000" />
			</geometry>
		</collision>
	</link>
	<link name="ee_link">
		<inertial>
			<origin rpy="0.00000 -0.00000 0.00000" xyz="0.00000 0.00000 0.00000" />
			<mass value="1.00000" />
			<inertia ixx="0.00002" ixy="0" ixz="0" iyy="0.00002" iyz="0" izz="0.00002" />
		</inertial>
		<visual>
			<origin rpy="0.00000 -0.00000 0.00000" xyz="-0.01000 0.00000 0.00000" />
			<geometry>
				<box size="0.01000 0.01000 0.01000" />
			</geometry>
			<material name="7">
				<color rgba="1.00000 1.00000 1.00000 1.00000" />
			</material>
		</visual>
		<collision>
			<origin rpy="0.00000 -0.00000 0.00000" xyz="-0.01000 0.00000 0.00000" />
			<geometry>
				<box size="0.01000 0.01000 0.01000" />
			</geometry>
		</collision>
	</link>
	<link name="tool0">
		<inertial>
			<origin rpy="0.00000 -0.00000 0.00000" xyz="0.00000 0.00000 0.00000" />
			<mass value="1.00000" />
			<inertia ixx="0.00000" ixy="0" ixz="0" iyy="0.00000" iyz="0" izz="0.00000" />
		</inertial>
	</link>
	<link name="base">
		<inertial>
			<origin rpy="0.00000 -0.00000 0.00000" xyz="0.00000 0.00000 0.00000" />
			<mass value="1.00000" />
			<inertia ixx="0.00000" ixy="0" ixz="0" iyy="0.00000" iyz="0" izz="0.00000" />
		</inertial>
	</link>
	<link name="root">
		<inertial>
			<origin rpy="0.00000 -0.00000 0.00000" xyz="-0.01448 -0.00427 0.02204" />
			<mass value="10.00000" />
			<inertia ixx="0.17377" ixy="0" ixz="0" iyy="0.14938" iyz="0" izz="0.03532" />
		</inertial>
		<visual>
			<origin rpy="0.00000 -0.00000 0.00000" xyz="-0.01459 -0.00427 0.02232" />
			<geometry>
				<mesh filename="rlbotics/envs/models/end_effectors/welding_torches/welding_torch/meshes/dae/Body1.dae" scale="0.01000 0.01000 0.01000" />
			</geometry>
			<material name="8">
				<color rgba="0.80000 0.80000 0.80000 1.00000" />
			</material>
		</visual>
		<visual>
			<origin rpy="0.00000 -0.00000 0.00000" xyz="-0.01459 -0.00427 0.02232" />
			<geometry>
				<mesh filename="rlbotics/envs/models/end_effectors/welding_torches/welding_torch/meshes/dae/Body10.dae" scale="0.01000 0.01000 0.01000" />
			</geometry>
			<material name="9">
				<color rgba="0.80000 0.64627 0.39843 1.00000" />
			</material>
		</visual>
		<visual>
			<origin rpy="0.00000 -0.00000 0.00000" xyz="-0.01459 -0.00427 0.02232" />
			<geometry>
				<mesh filename="rlbotics/envs/models/end_effectors/welding_torches/welding_torch/meshes/dae/Body11.dae" scale="0.01000 0.01000 0.01000" />
			</geometry>
			<material name="10">
				<color rgba="0.80000 0.64627 0.39843 1.00000" />
			</material>
		</visual>
		<visual>
			<origin rpy="0.00000 -0.00000 0.00000" xyz="-0.01459 -0.00427 0.02232" />
			<geometry>
				<mesh filename="rlbotics/envs/models/end_effectors/welding_torches/welding_torch/meshes/dae/Body12.dae" scale="0.01000 0.01000 0.01000" />
			</geometry>
			<material name="11">
				<color rgba="0.63373 0.65569 0.74667 1.00000" />
			</material>
		</visual>
		<visual>
			<origin rpy="0.00000 -0.00000 0.00000" xyz="-0.01459 -0.00427 0.02232" />
			<geometry>
				<mesh filename="rlbotics/envs/models/end_effectors/welding_torches/welding_torch/meshes/dae/Body13.dae" scale="0.01000 0.01000 0.01000" />
			</geometry>
			<material name="12">
				<color rgba="0.71843 0.73412 0.74353 1.00000" />
			</material>
		</visual>
		<visual>
			<origin rpy="0.00000 -0.00000 0.00000" xyz="-0.01459 -0.00427 0.02232" />
			<geometry>
				<mesh filename="rlbotics/envs/models/end_effectors/welding_torches/welding_torch/meshes/dae/Body14.dae" scale="0.01000 0.01000 0.01000" />
			</geometry>
			<material name="13">
				<color rgba="0.63373 0.65569 0.74667 1.00000" />
			</material>
		</visual>
		<visual>
			<origin rpy="0.00000 -0.00000 0.00000" xyz="-0.01459 -0.00427 0.02232" />
			<geometry>
				<mesh filename="rlbotics/envs/models/end_effectors/welding_torches/welding_torch/meshes/dae/Body15.dae" scale="0.01000 0.01000 0.01000" />
			</geometry>
			<material name="14">
				<color rgba="0.80000 0.64627 0.39843 1.00000" />
			</material>
		</visual>
		<visual>
			<origin rpy="0.00000 -0.00000 0.00000" xyz="-0.01459 -0.00427 0.02232" />
			<geometry>
				<mesh filename="rlbotics/envs/models/end_effectors/welding_torches/welding_torch/meshes/dae/Body16.dae" scale="0.01000 0.01000 0.01000" />
			</geometry>
			<material name="15">
				<color rgba="0.63373 0.65569 0.74667 1.00000" />
			</material>
		</visual>
		<visual>
			<origin rpy="0.00000 -0.00000 0.00000" xyz="-0.01459 -0.00427 0.02232" />
			<geometry>
				<mesh filename="rlbotics/envs/models/end_effectors/welding_torches/welding_torch/meshes/dae/Body17.dae" scale="0.01000 0.01000 0.01000" />
			</geometry>
			<material name="16">
				<color rgba="0.63373 0.65569 0.74667 1.00000" />
			</material>
		</visual>
		<visual>
			<origin rpy="0.00000 -0.00000 0.00000" xyz="-0.01459 -0.00427 0.02232" />
			<geometry>
				<mesh filename="rlbotics/envs/models/end_effectors/welding_torches/welding_torch/meshes/dae/Body18.dae" scale="0.01000 0.01000 0.01000" />
			</geometry>
			<material name="17">
				<color rgba="0.63373 0.65569 0.74667 1.00000" />
			</material>
		</visual>
		<visual>
			<origin rpy="0.00000 -0.00000 0.00000" xyz="-0.01459 -0.00427 0.02232" />
			<geometry>
				<mesh filename="rlbotics/envs/models/end_effectors/welding_torches/welding_torch/meshes/dae/Body19.dae" scale="0.01000 0.01000 0.01000" />
			</geometry>
			<material name="18">
				<color rgba="0.63373 0.65569 0.74667 1.00000" />
			</material>
		</visual>
		<visual>
			<origin rpy="0.00000 -0.00000 0.00000" xyz="-0.01459 -0.00427 0.02232" />
			<geometry>
				<mesh filename="rlbotics/envs/models/end_effectors/welding_torches/welding_torch/meshes/dae/Body2.dae" scale="0.01000 0.01000 0.01000" />
			</geometry>
			<material name="19">
				<color rgba="0.54902 0.48627 0.42353 1.00000" />
			</material>
		</visual>
		<visual>
			<origin rpy="0.00000 -0.00000 0.00000" xyz="-0.01459 -0.00427 0.02232" />
			<geometry>
				<mesh filename="rlbotics/envs/models/end_effectors/welding_torches/welding_torch/meshes/dae/Body20.dae" scale="0.01000 0.01000 0.01000" />
			</geometry>
			<material name="20">
				<color rgba="0.63373 0.65569 0.74667 1.00000" />
			</material>
		</visual>
		<visual>
			<origin rpy="0.00000 -0.00000 0.00000" xyz="-0.01459 -0.00427 0.02232" />
			<geometry>
				<mesh filename="rlbotics/envs/models/end_effectors/welding_torches/welding_torch/meshes/dae/Body21.dae" scale="0.01000 0.01000 0.01000" />
			</geometry>
			<material name="21">
				<color rgba="0.80000 0.64627 0.39843 1.00000" />
			</material>
		</visual>
		<visual>
			<origin rpy="0.00000 -0.00000 0.00000" xyz="-0.01459 -0.00427 0.02232" />
			<geometry>
				<mesh filename="rlbotics/envs/models/end_effectors/welding_torches/welding_torch/meshes/dae/Body23.dae" scale="0.01000 0.01000 0.01000" />
			</geometry>
			<material name="22">
				<color rgba="0.23843 0.23843 0.23843 1.00000" />
			</material>
		</visual>
		<visual>
			<origin rpy="0.00000 -0.00000 0.00000" xyz="-0.01459 -0.00427 0.02232" />
			<geometry>
				<mesh filename="rlbotics/envs/models/end_effectors/welding_torches/welding_torch/meshes/dae/Body24.dae" scale="0.01000 0.01000 0.01000" />
			</geometry>
			<material name="23">
				<color rgba="0.80000 0.64627 0.39843 1.00000" />
			</material>
		</visual>
		<visual>
			<origin rpy="0.00000 -0.00000 0.00000" xyz="-0.01459 -0.00427 0.02232" />
			<geometry>
				<mesh filename="rlbotics/envs/models/end_effectors/welding_torches/welding_torch/meshes/dae/Body25.dae" scale="0.01000 0.01000 0.01000" />
			</geometry>
			<material name="24">
				<color rgba="0.23843 0.23843 0.23843 1.00000" />
			</material>
		</visual>
		<visual>
			<origin rpy="0.00000 -0.00000 0.00000" xyz="-0.01459 -0.00427 0.02232" />
			<geometry>
				<mesh filename="rlbotics/envs/models/end_effectors/welding_torches/welding_torch/meshes/dae/Body26.dae" scale="0.01000 0.01000 0.01000" />
			</geometry>
			<material name="25">
				<color rgba="0.62118 0.55843 0.51137 1.00000" />
			</material>
		</visual>
		<visual>
			<origin rpy="0.00000 -0.00000 0.00000" xyz="-0.01459 -0.00427 0.02232" />
			<geometry>
				<mesh filename="rlbotics/envs/models/end_effectors/welding_torches/welding_torch/meshes/dae/Body27.dae" scale="0.01000 0.01000 0.01000" />
			</geometry>
			<material name="26">
				<color rgba="0.67137 0.37333 0.29490 1.00000" />
			</material>
		</visual>
		<visual>
			<origin rpy="0.00000 -0.00000 0.00000" xyz="-0.01459 -0.00427 0.02232" />
			<geometry>
				<mesh filename="rlbotics/envs/models/end_effectors/welding_torches/welding_torch/meshes/dae/Body3.dae" scale="0.01000 0.01000 0.01000" />
			</geometry>
			<material name="27">
				<color rgba="0.62118 0.60549 0.58980 1.00000" />
			</material>
		</visual>
		<visual>
			<origin rpy="0.00000 -0.00000 0.00000" xyz="-0.01459 -0.00427 0.02232" />
			<geometry>
				<mesh filename="rlbotics/envs/models/end_effectors/welding_torches/welding_torch/meshes/dae/Body4.dae" scale="0.01000 0.01000 0.01000" />
			</geometry>
			<material name="28">
				<color rgba="0.80000 0.62431 0.52706 1.00000" />
			</material>
		</visual>
		<visual>
			<origin rpy="0.00000 -0.00000 0.00000" xyz="-0.01459 -0.00427 0.02232" />
			<geometry>
				<mesh filename="rlbotics/envs/models/end_effectors/welding_torches/welding_torch/meshes/dae/Body5.dae" scale="0.01000 0.01000 0.01000" />
			</geometry>
			<material name="29">
				<color rgba="1.00000 1.00000 1.00000 1.00000" />
			</material>
		</visual>
		<visual>
			<origin rpy="0.00000 -0.00000 0.00000" xyz="-0.01459 -0.00427 0.02232" />
			<geometry>
				<mesh filename="rlbotics/envs/models/end_effectors/welding_torches/welding_torch/meshes/dae/Body6.dae" scale="0.01000 0.01000 0.01000" />
			</geometry>
			<material name="30">
				<color rgba="0.16000 0.16000 0.16000 1.00000" />
			</material>
		</visual>
		<visual>
			<origin rpy="0.00000 -0.00000 0.00000" xyz="-0.01459 -0.00427 0.02232" />
			<geometry>
				<mesh filename="rlbotics/envs/models/end_effectors/welding_torches/welding_torch/meshes/dae/Body7.dae" scale="0.01000 0.01000 0.01000" />
			</geometry>
			<material name="31">
				<color rgba="0.80000 0.64627 0.39843 1.00000" />
			</material>
		</visual>
		<visual>
			<origin rpy="0.00000 -0.00000 0.00000" xyz="-0.01459 -0.00427 0.02232" />
			<geometry>
				<mesh filename="rlbotics/envs/models/end_effectors/welding_torches/welding_torch/meshes/dae/Body8.dae" scale="0.01000 0.01000 0.01000" />
			</geometry>
			<material name="32">
				<color rgba="0.80000 0.64627 0.39843 1.00000" />
			</material>
		</visual>
		<visual>
			<origin rpy="0.00000 -0.00000 0.00000" xyz="-0.01459 -0.00427 0.02232" />
			<geometry>
				<mesh filename="rlbotics/envs/models/end_effectors/welding_torches/welding_torch/meshes/dae/Body9.dae" scale="0.01000 0.01000 0.01000" />
			</geometry>
			<material name="33">
				<color rgba="0.80000 0.64627 0.39843 1.00000" />
			</material>
		</visual>
		<collision>
			<origin rpy="0.00000 -0.00000 0.00000" xyz="-0.01408 -0.00470 0.02250" />
			<geometry>
				<mesh filename="rlbotics/envs/models/end_effectors/welding_torches/welding_torch/meshes/dae/Body1.001.dae" scale="1.00000 1.00000 1.00000" />
			</geometry>
		</collision>
		<collision>
			<origin rpy="0.00000 -0.00000 0.00000" xyz="-0.01585 -0.00436 0.02222" />
			<geometry>
				<mesh filename="rlbotics/envs/models/end_effectors/welding_torches/welding_torch/meshes/dae/Body23.001.dae" scale="1.00000 1.00000 1.00000" />
			</geometry>
		</collision>
		<collision>
			<origin rpy="0.00000 -0.00000 0.00000" xyz="-0.01479 -0.00422 0.02305" />
			<geometry>
				<mesh filename="rlbotics/envs/models/end_effectors/welding_torches/welding_torch/meshes/dae/Body24.001.dae" scale="1.00000 1.00000 1.00000" />
			</geometry>
		</collision>
		<collision>
			<origin rpy="0.00000 -0.00000 0.00000" xyz="-0.01463 -0.00463 0.02662" />
			<geometry>
				<mesh filename="rlbotics/envs/models/end_effectors/welding_torches/welding_torch/meshes/dae/Body25.001.dae" scale="1.00000 1.00000 1.00000" />
			</geometry>
		</collision>
		<collision>
			<origin rpy="0.00000 -0.00000 0.00000" xyz="-0.01408 -0.00373 0.02106" />
			<geometry>
				<mesh filename="rlbotics/envs/models/end_effectors/welding_torches/welding_torch/meshes/dae/Body3.001.dae" scale="1.00000 1.00000 1.00000" />
			</geometry>
		</collision>
		<collision>
			<origin rpy="0.00000 -0.00000 0.00000" xyz="-0.01390 -0.00438 0.02201" />
			<geometry>
				<mesh filename="rlbotics/envs/models/end_effectors/welding_torches/welding_torch/meshes/dae/Body5.001.dae" scale="1.00000 1.00000 1.00000" />
			</geometry>
		</collision>
		<collision>
			<origin rpy="0.00000 -0.00000 0.00000" xyz="-0.01448 -0.00416 0.02241" />
			<geometry>
				<mesh filename="rlbotics/envs/models/end_effectors/welding_torches/welding_torch/meshes/dae/Body6.001.dae" scale="1.00000 1.00000 1.00000" />
			</geometry>
		</collision>
	</link>
	<link name="ee_joint_arm">
		<inertial>
			<origin rpy="0.00000 -0.00000 0.00000" xyz="-0.01458 -0.00585 0.05244" />
			<mass value="2.00000" />
			<inertia ixx="0.00131" ixy="0" ixz="0" iyy="0.00131" iyz="0" izz="0.00247" />
		</inertial>
		<visual>
			<origin rpy="0.00000 -0.00000 0.00000" xyz="-0.01462 -0.00586 0.05218" />
			<geometry>
				<mesh filename="rlbotics/envs/models/end_effectors/welding_torches/welding_torch/meshes/dae/Body22.dae" scale="0.01000 0.01000 0.01000" />
			</geometry>
			<material name="34">
				<color rgba="0.63373 0.65569 0.74667 1.00000" />
			</material>
		</visual>
		<collision>
			<origin rpy="0.00000 -0.00000 0.00000" xyz="-0.01458 -0.00585 0.05244" />
			<geometry>
				<mesh filename="rlbotics/envs/models/end_effectors/welding_torches/welding_torch/meshes/dae/Body22.001.dae" scale="1.00000 1.00000 1.00000" />
			</geometry>
		</collision>
	</link>
	<link name="nozzle_tip">
		<inertial>
			<origin rpy="0.00000 -0.00000 0.00000" xyz="-0.01570 -0.30904 -0.22158" />
			<mass value="2.00000" />
			<inertia ixx="0.00118" ixy="0" ixz="0" iyy="0.00073" iyz="0" izz="0.00072" />
		</inertial>
		<visual>
			<origin rpy="-0.92502 0.00000 0.00000" xyz="-0.01560 -0.30844 -0.21793" />
			<geometry>
				<mesh filename="rlbotics/envs/models/end_effectors/welding_torches/welding_torch/meshes/dae/Body28.dae" scale="0.01000 0.01000 0.01000" />
			</geometry>
			<material name="35">
				<color rgba="0.67137 0.37333 0.29490 1.00000" />
			</material>
		</visual>
		<collision>
			<origin rpy="-0.92502 0.00000 0.00000" xyz="-0.01570 -0.30904 -0.22158" />
			<geometry>
				<mesh filename="rlbotics/envs/models/end_effectors/welding_torches/welding_torch/meshes/dae/Body28.001.dae" scale="1.00000 1.00000 1.00000" />
			</geometry>
		</collision>
	</link>
	<joint name="world_joint" type="fixed">
		<parent link="world" />
		<child link="base_link" />
		<dynamics damping="1.0" friction="0.0001" />
		<origin rpy="0.00000 -0.00000 0.00000" xyz="0.00000 0.00000 0.00000" />
		<axis xyz="0.00000 0.00000 0.00000" />
	</joint>
	<joint name="shoulder_pan_joint" type="revolute">
		<parent link="base_link" />
		<child link="shoulder_link" />
		<dynamics damping="0.0" friction="0.0" />
		<origin rpy="0.00000 -0.00000 0.00000" xyz="0.00000 0.00000 0.12730" />
		<axis xyz="0.00000 0.00000 1.00000" />
	<limit effort="330.0" lower="-6.283185307179586" upper="6.283185307179586" velocity="2.16" /></joint>
	<joint name="shoulder_lift_joint" type="revolute">
		<parent link="shoulder_link" />
		<child link="upper_arm_link" />
		<dynamics damping="0.0" friction="0.0" />
		<origin rpy="0.00000 1.57080 -0.00000" xyz="0.00000 0.22094 0.00000" />
		<axis xyz="0.00000 1.00000 0.00000" />
	<limit effort="330.0" lower="-6.283185307179586" upper="6.283185307179586" velocity="2.16" /></joint>
	<joint name="elbow_joint" type="revolute">
		<parent link="upper_arm_link" />
		<child link="forearm_link" />
		<dynamics damping="0.0" friction="0.0" />
		<origin rpy="0.00000 -0.00000 0.00000" xyz="0.00000 -0.17190 0.61200" />
		<axis xyz="0.00000 1.00000 0.00000" />
	<limit effort="150.0" lower="-3.141592653589793" upper="3.141592653589793" velocity="3.15" /></joint>
	<joint name="wrist_1_joint" type="revolute">
		<parent link="forearm_link" />
		<child link="wrist_1_link" />
		<dynamics damping="0.0" friction="0.0" />
		<origin rpy="0.00000 1.57080 -0.00000" xyz="0.00000 0.00000 0.57230" />
		<axis xyz="0.00000 1.00000 0.00000" />
	<limit effort="54.0" lower="-6.283185307179586" upper="6.283185307179586" velocity="3.2" /></joint>
	<joint name="wrist_2_joint" type="revolute">
		<parent link="wrist_1_link" />
		<child link="wrist_2_link" />
		<dynamics damping="0.0" friction="0.0" />
		<origin rpy="0.00000 -0.00000 0.00000" xyz="0.00000 0.11490 0.00000" />
		<axis xyz="0.00000 0.00000 1.00000" />
	<limit effort="54.0" lower="-6.283185307179586" upper="6.283185307179586" velocity="3.2" /></joint>
	<joint name="wrist_3_joint" type="revolute">
		<parent link="wrist_2_link" />
		<child link="wrist_3_link" />
		<dynamics damping="0.0" friction="0.0" />
		<origin rpy="0.00000 -0.00000 0.00000" xyz="0.00000 0.00000 0.11570" />
		<axis xyz="0.00000 0.00000 -1.00000" />
	<limit effort="54.0" lower="-6.283185307179586" upper="6.283185307179586" velocity="3.2" /></joint>
	<joint name="ee_fixed_joint" type="fixed">
		<parent link="wrist_3_link" />
		<child link="ee_link" />
		<dynamics damping="1.0" friction="0.0001" />
		<origin rpy="0.00000 -0.00000 1.57080" xyz="0.00000 0.09220 0.00000" />
		<axis xyz="0.00000 0.00000 0.00000" />
	</joint>
	<joint name="wrist_3_link-tool0_fixed_joint" type="fixed">
		<parent link="wrist_3_link" />
		<child link="tool0" />
		<dynamics damping="1.0" friction="0.0001" />
		<origin rpy="-1.57080 0.00000 0.00000" xyz="0.00000 0.09220 0.00000" />
		<axis xyz="0.00000 0.00000 0.00000" />
	</joint>
	<joint name="base_link-base_fixed_joint" type="fixed">
		<parent link="base_link" />
		<child link="base" />
		<dynamics damping="1.0" friction="0.0001" />
		<origin rpy="0.00000 -0.00000 -3.14159" xyz="0.00000 0.00000 0.00000" />
		<axis xyz="0.00000 0.00000 0.00000" />
	</joint>
	<joint name="joint_dummy1" type="fixed">
		<parent link="ee_link" />
		<child link="root" />
		<dynamics damping="1.0" friction="0.0001" />
		<origin rpy="3.14159 1.57080 0.00000" xyz="0.00000 0.00000 0.00000" />
		<axis xyz="0.00000 0.00000 1.00000" />
	</joint>
	<joint name="ee_joint_arm" type="fixed">
		<parent link="root" />
		<child link="ee_joint_arm" />
		<dynamics damping="1.0" friction="0.0001" />
		<origin rpy="0.00000 -0.00000 0.00000" xyz="0.00003 0.00159 -0.02985" />
		<axis xyz="0.00000 0.00000 0.00000" />
	</joint>
	<joint name="nozzle_tip" type="fixed">
		<parent link="root" />
		<child link="nozzle_tip" />
		<dynamics damping="1.0" friction="0.0001" />
		<origin rpy="0.92502 -0.00000 0.00000" xyz="0.00101 0.00731 0.39981" />
		<axis xyz="0.00000 0.00000 0.00000" />
	</joint>
</robot>